<?xml version="1.0"?>

<robot xmlns:xacro="http://www.ros.org/wiki/xacro">
    
    <!-- LEFT WHEEL LINK -->

    <joint name="left_wheel_joint" type="continuous">
        <parent link="base_link"/>
        <child link="left_wheel"/>
        <origin xyz="0.0 0.4 0.0" rpy="-${pi/2} 0.0 0.0"/>
        <axis xyz="0.0 0.0 1.0"/>
    </joint>

    <link name="left_wheel">
        <visual>
            <geometry>
                <cylinder radius="0.14" length="0.1"/>
            </geometry>
            <material name="dark_gray"/>
        </visual>
        <collision>
            <geometry>
                <cylinder radius="0.14" length="0.1"/>
            </geometry>
        </collision>
        <xacro:inertial_cylinder mass="0.3" radius="0.14" length="0.1">
            <origin xyz="0.0 0.0 0.0" rpy="0.0 0.0 0.0"/>
        </xacro:inertial_cylinder>
    </link>

    <!-- RIGHT WHEEL LINK -->

    <joint name="right_wheel_joint" type="continuous">
        <parent link="base_link"/>
        <child link="right_wheel"/>
        <origin xyz="0.0 -0.4 0.0" rpy="${pi/2} 0.0 0.0"/>
        <axis xyz="0.0 0.0 -1.0"/>
    </joint>

    <link name="right_wheel">
        <visual>
            <geometry>
                <cylinder radius="0.14" length="0.1"/>
            </geometry>
            <material name="dark_gray"/>
        </visual>
        <collision>
            <geometry>
                <cylinder radius="0.14" length="0.1"/>
            </geometry>
        </collision>
        <xacro:inertial_cylinder mass="0.3" radius="0.14" length="0.1">
            <origin xyz="0.0 0.0 0.0" rpy="0.0 0.0 0.0"/>
        </xacro:inertial_cylinder>
    </link>

    <!-- LEFT CASTER WHEEL LINK -->

    <joint name="left_caster_wheel_joint" type="fixed">
        <parent link="base_link"/>
        <child link="left_caster_wheel"/>
        <origin xyz="0.6 0.4 0.0" rpy="-${pi/2} 0.0 0.0"/>
    </joint>


    <link name="left_caster_wheel">
        <visual>
            <geometry>
                <cylinder radius="0.14" length="0.1"/>
            </geometry>
            <material name="dark_gray"/>
        </visual>
        <collision>
            <geometry>
                <cylinder radius="0.14" length="0.1"/>
            </geometry>
        </collision>
        <xacro:inertial_cylinder mass="0.3" radius="0.14" length="0.1">
            <origin xyz="0.0 0.0 0.0" rpy="0.0 0.0 0.0"/>
        </xacro:inertial_cylinder>
    </link>

    <!-- RIGHT CASTER WHEEL LINK -->

    <joint name="right_caster_wheel_joint" type="fixed">
        <parent link="base_link"/>
        <child link="right_caster_wheel"/>
        <origin xyz="0.6 -0.4 0.0" rpy="${pi/2} 0.0 0.0"/>
    </joint>

    <link name="right_caster_wheel">
        <visual>
            <geometry>
                <cylinder radius="0.14" length="0.1"/>
            </geometry>
            <material name="dark_gray"/>
        </visual>
        <collision>
            <geometry>
                <cylinder radius="0.14" length="0.1"/>
            </geometry>
        </collision>
        <xacro:inertial_cylinder mass="0.3" radius="0.14" length="0.1">
            <origin xyz="0.0 0.0 0.0" rpy="0.0 0.0 0.0"/>
        </xacro:inertial_cylinder>
    </link>

    <gazebo reference="left_caster_wheel">
        <mu1 value="0.0001"/>
        <mu2 value="0.0001"/>
    </gazebo>

    <gazebo reference="right_caster_wheel">
        <mu1 value="0.0001"/>
        <mu2 value="0.0001"/>
    </gazebo>
</robot>